Workbook

Sheet 시산표
A2: 시산표
A4: 기간 | B4: 2026-10 | D4: 전체 기간은 * 입력 | F4: 단위: 원
A6: 핵심 결과
A7: 총 차변 합계 | B7: =SUMIFS(전표!$F$7:$F$282,전표!$K$7:$K$282,$B$4) -> 106592717
A8: 총 대변 합계 | B8: =SUMIFS(전표!$G$7:$G$282,전표!$K$7:$K$282,$B$4) -> 106592717
A9: 차액 | B9: =B7-B8 -> 0
A10: 판정 | B10: =IF(ABS(B9)<1,"일치","불일치 (원장 확인 필요)") -> 일치
A12: 손익 요약
A13: 수익 합계 | B13: =SUMIFS(전표!$G$7:$G$282,전표!$M$7:$M$282,"수익",전표!$K$7:$K$282,$B$4)-SUMIFS(전표!$F$7:$F$282,전표!$M$7:$M$282,"수익",전표!$K$7:$K$282,$B$4) -> 3155500
A14: 비용 합계 | B14: =SUMIFS(전표!$F$7:$F$282,전표!$M$7:$M$282,"비용",전표!$K$7:$K$282,$B$4)-SUMIFS(전표!$G$7:$G$282,전표!$M$7:$M$282,"비용",전표!$K$7:$K$282,$B$4) -> 43050000
A15: 당기순손익 | B15: =B13-B14 -> -39894500 | C15: =IF(B15>0,"흑자",IF(B15<0,"적자","손익 없음")) -> 적자
A17: 부가세 신고자료
A18: 과세 매출 공급가액 | B18: =SUMIFS(전표!$G$7:$G$282,전표!$M$7:$M$282,"수익",전표!$N$7:$N$282,"과세",전표!$K$7:$K$282,$B$4)-SUMIFS(전표!$F$7:$F$282,전표!$M$7:$M$282,"수익",전표!$N$7:$N$282,"과세",전표!$K$7:$K$282,$B$4) -> 3155500
A19: 매출세액 | B19: =SUMIFS(전표!$H$7:$H$282,전표!$M$7:$M$282,"수익",전표!$N$7:$N$282,"과세",전표!$K$7:$K$282,$B$4) -> 307677
A20: 과세 매입 공급가액 | B20: =SUMIFS(전표!$F$7:$F$282,전표!$M$7:$M$282,"비용",전표!$N$7:$N$282,"과세",전표!$K$7:$K$282,$B$4)+SUMIFS(전표!$F$7:$F$282,전표!$M$7:$M$282,"자산",전표!$N$7:$N$282,"과세",전표!$K$7:$K$282,$B$4) -> 43050000
A21: 매입세액 | B21: =SUMIFS(전표!$H$7:$H$282,전표!$M$7:$M$282,"비용",전표!$N$7:$N$282,"과세",전표!$K$7:$K$282,$B$4)+SUMIFS(전표!$H$7:$H$282,전표!$M$7:$M$282,"자산",전표!$N$7:$N$282,"과세",전표!$K$7:$K$282,$B$4) -> 4305000
A22: 납부(환급) 예상세액 | B22: =B19-B21 -> -3997323
A23: 부가세액은 공급가액이 있는 라인(수익·비용 계정)에 입력합니다. 면세·간이과세 거래와 신고 전 세무 검토는 반영되지 않습니다.
A25: 계정별 시산표
A26: 코드 | B26: 계정명 | C26: 유형 | D26: 차변 | E26: 대변 | F26: 잔액
A27: =계정과목!A6 -> 101 | B27: =계정과목!B6 -> 현금 | C27: =계정과목!C6 -> 자산 | D27: =SUMIFS(전표!$F$7:$F$282,전표!$E$7:$E$282,$A27,전표!$K$7:$K$282,$B$4) -> 47600 | E27: =SUMIFS(전표!$G$7:$G$282,전표!$E$7:$E$282,$A27,전표!$K$7:$K$282,$B$4) -> 0 | F27: =D27-E27 -> 47600
A28: =계정과목!A7 -> 102 | B28: =계정과목!B7 -> 보통예금 | C28: =계정과목!C7 -> 자산 | D28: =SUMIFS(전표!$F$7:$F$282,전표!$E$7:$E$282,$A28,전표!$K$7:$K$282,$B$4) -> 43300000 | E28: =SUMIFS(전표!$G$7:$G$282,전표!$E$7:$E$282,$A28,전표!$K$7:$K$282,$B$4) -> 15766667 | F28: =D28-E28 -> 27533333
A29: =계정과목!A9 -> 104 | B29: =계정과목!B9 -> 상품권 | C29: =계정과목!C9 -> 자산 | D29: =SUMIFS(전표!$F$7:$F$282,전표!$E$7:$E$282,$A29,전표!$K$7:$K$282,$B$4) -> 30000 | E29: =SUMIFS(전표!$G$7:$G$282,전표!$E$7:$E$282,$A29,전표!$K$7:$K$282,$B$4) -> 0 | F29: =D29-E29 -> 30000
A30: =계정과목!A10 -> 120 | B30: =계정과목!B10 -> 외상매출금 | C30: =계정과목!C10 -> 자산 | D30: =SUMIFS(전표!$F$7:$F$282,전표!$E$7:$E$282,$A30,전표!$K$7:$K$282,$B$4) -> 0 | E30: =SUMIFS(전표!$G$7:$G$282,전표!$E$7:$E$282,$A30,전표!$K$7:$K$282,$B$4) -> 0 | F30: =D30-E30 -> 0
A31: =계정과목!A11 -> 135 | B31: =계정과목!B11 -> 부가세대급금 | C31: =계정과목!C11 -> 자산 | D31: =SUMIFS(전표!$F$7:$F$282,전표!$E$7:$E$282,$A31,전표!$K$7:$K$282,$B$4) -> 4305000 | E31: =SUMIFS(전표!$G$7:$G$282,전표!$E$7:$E$282,$A31,전표!$K$7:$K$282,$B$4) -> 0 | F31: =D31-E31 -> 4305000
A32: =계정과목!A12 -> 141 | B32: =계정과목!B12 -> 미수금 | C32: =계정과목!C12 -> 자산 | D32: =SUMIFS(전표!$F$7:$F$282,전표!$E$7:$E$282,$A32,전표!$K$7:$K$282,$B$4) -> 0 | E32: =SUMIFS(전표!$G$7:$G$282,전표!$E$7:$E$282,$A32,전표!$K$7:$K$282,$B$4) -> 0 | F32: =D32-E32 -> 0
A33: =계정과목!A13 -> 150 | B33: =계정과목!B13 -> 상품 | C33: =계정과목!C13 -> 자산 | D33: =SUMIFS(전표!$F$7:$F$282,전표!$E$7:$E$282,$A33,전표!$K$7:$K$282,$B$4) -> 0 | E33: =SUMIFS(전표!$G$7:$G$282,전표!$E$7:$E$282,$A33,전표!$K$7:$K$282,$B$4) -> 0 | F33: =D33-E33 -> 0
A34: =계정과목!A14 -> 160 | B34: =계정과목!B14 -> 비품 | C34: =계정과목!C14 -> 자산 | D34: =SUMIFS(전표!$F$7:$F$282,전표!$E$7:$E$282,$A34,전표!$K$7:$K$282,$B$4) -> 0 | E34: =SUMIFS(전표!$G$7:$G$282,전표!$E$7:$E$282,$A34,전표!$K$7:$K$282,$B$4) -> 0 | F34: =D34-E34 -> 0
A35: =계정과목!A15 -> 165 | B35: =계정과목!B15 -> 시설장치 | C35: =계정과목!C15 -> 자산 | D35: =SUMIFS(전표!$F$7:$F$282,전표!$E$7:$E$282,$A35,전표!$K$7:$K$282,$B$4) -> 0 | E35: =SUMIFS(전표!$G$7:$G$282,전표!$E$7:$E$282,$A35,전표!$K$7:$K$282,$B$4) -> 0 | F35: =D35-E35 -> 0
A36: =계정과목!A16 -> 170 | B36: =계정과목!B16 -> 감가상각누계액 | C36: =계정과목!C16 -> 자산 | D36: =SUMIFS(전표!$F$7:$F$282,전표!$E$7:$E$282,$A36,전표!$K$7:$K$282,$B$4) -> 0 | E36: =SUMIFS(전표!$G$7:$G$282,전표!$E$7:$E$282,$A36,전표!$K$7:$K$282,$B$4) -> 0 | F36: =D36-E36 -> 0
A37: =계정과목!A17 -> 180 | B37: =계정과목!B17 -> 임차보증금 | C37: =계정과목!C17 -> 자산 | D37: =SUMIFS(전표!$F$7:$F$282,전표!$E$7:$E$282,$A37,전표!$K$7:$K$282,$B$4) -> 0 | E37: =SUMIFS(전표!$G$7:$G$282,전표!$E$7:$E$282,$A37,전표!$K$7:$K$282,$B$4) -> 0 | F37: =D37-E37 -> 0
A38: =계정과목!A18 -> 190 | B38: =계정과목!B18 -> 선급비용 | C38: =계정과목!C18 -> 자산 | D38: =SUMIFS(전표!$F$7:$F$282,전표!$E$7:$E$282,$A38,전표!$K$7:$K$282,$B$4) -> 0 | E38: =SUMIFS(전표!$G$7:$G$282,전표!$E$7:$E$282,$A38,전표!$K$7:$K$282,$B$4) -> 0 | F38: =D38-E38 -> 0
A39: =계정과목!A19 -> 201 | B39: =계정과목!B19 -> 외상매입금 | C39: =계정과목!C19 -> 부채 | D39: =SUMIFS(전표!$F$7:$F$282,전표!$E$7:$E$282,$A39,전표!$K$7:$K$282,$B$4) -> 0 | E39: =SUMIFS(전표!$G$7:$G$282,전표!$E$7:$E$282,$A39,전표!$K$7:$K$282,$B$4) -> 0 | F39: =D39-E39 -> 0
A40: =계정과목!A20 -> 202 | B40: =계정과목!B20 -> 미지급금 | C40: =계정과목!C20 -> 부채 | D40: =SUMIFS(전표!$F$7:$F$282,전표!$E$7:$E$282,$A40,전표!$K$7:$K$282,$B$4) -> 15766667 | E40: =SUMIFS(전표!$G$7:$G$282,전표!$E$7:$E$282,$A40,전표!$K$7:$K$282,$B$4) -> 47355000 | F40: =D40-E40 -> -31588333
... A78: =계정과목!A58 -> 540 | B78: =계정과목!B58 -> 이자비용 | C78: =계정과목!C58 -> 비용 | D78: =SUMIFS(전표!$F$7:$F$282,전표!$E$7:$E$282,$A78,전표!$K$7:$K$282,$B$4) -> 0 | E78: =SUMIFS(전표!$G$7:$G$282,전표!$E$7:$E$282,$A78,전표!$K$7:$K$282,$B$4) -> 0 | F78: =D78-E78 -> 0
A79: 합계 | D79: =SUM(D27:D78) -> 106499267 | E79: =SUM(E27:E78) -> 106592717 | F79: =SUM(F27:F78) -> -93450

Sheet 전표
A2: 전표 입력
A3: 같은 전표번호의 차변 합계와 대변 합계는 같아야 합니다. | E3: 테두리자동화
A4: 계정코드는 '계정과목' 시트에서 선택합니다. 아래 샘플 전표는 지우고 사용하십시오.
A6: 전표번호 | B6: 날짜 | C6: 증빙 | D6: 적요 | E6: 계정코드 | F6: 차변 | G6: 대변 | H6: 부가세액 | I6: 거래처 | J6: 비고 | K6: 기간 | L6: 계정명 | M6: 유형 | N6: 부가세구분 | O6: 등록여부 | P6: 전표 차대차액 | Q6: 차대 불일치 | R6: 전표교차
A7: V-2026-10-001 | B7: 46296 | C7: 기타 | D7: 자본금 납입 | E7: 102 | F7: 10000000 | I7: 대표 | J7: 개인자본 | K7: =IF($B7="","",TEXT($B7,"yyyy-mm")) -> 2026-10 | L7: =IF($E7="","",IFERROR(INDEX(계정과목!$B$6:$B$58,MATCH($E7,계정과목!$A$6:$A$58,0)),"미등록")) -> 보통예금 | M7: =IF($E7="","",IFERROR(INDEX(계정과목!$C$6:$C$58,MATCH($E7,계정과목!$A$6:$A$58,0)),"")) -> 자산 | N7: =IF($E7="","",IFERROR(INDEX(계정과목!$D$6:$D$58,MATCH($E7,계정과목!$A$6:$A$58,0)),"")) -> 해당없음 | O7: =IF($E7="","",IF(COUNTIF(계정과목!$A$6:$A$58,$E7)=0,"미등록","정상")) -> 정상 | P7: =IF($A7="","",ROUND(SUMIFS(전표!$F$7:$F$282,전표!$A$7:$A$282,$A7)-SUMIFS(전표!$G$7:$G$282,전표!$A$7:$A$282,$A7),0)) -> 0 | Q7: =IF(ISNUMBER($P7),IF(ABS($P7)>=1,1,0),0) -> 0 | R7: =IF($A7="","",0) -> 0
A8: V-2026-10-001 | B8: 46296 | C8: 기타 | D8: 자본금 납입 | E8: 301 | G8: 10000000 | I8: 대표 | J8: 개인자본 | K8: =IF($B8="","",TEXT($B8,"yyyy-mm")) -> 2026-10 | L8: =IF($E8="","",IFERROR(INDEX(계정과목!$B$6:$B$58,MATCH($E8,계정과목!$A$6:$A$58,0)),"미등록")) -> 자본금 | M8: =IF($E8="","",IFERROR(INDEX(계정과목!$C$6:$C$58,MATCH($E8,계정과목!$A$6:$A$58,0)),"")) -> 자본 | N8: =IF($E8="","",IFERROR(INDEX(계정과목!$D$6:$D$58,MATCH($E8,계정과목!$A$6:$A$58,0)),"")) -> 해당없음 | O8: =IF($E8="","",IF(COUNTIF(계정과목!$A$6:$A$58,$E8)=0,"미등록","정상")) -> 정상 | P8: =IF($A8="","",ROUND(SUMIFS(전표!$F$7:$F$282,전표!$A$7:$A$282,$A8)-SUMIFS(전표!$G$7:$G$282,전표!$A$7:$A$282,$A8),0)) -> 0 | Q8: =IF(ISNUMBER($P8),IF(ABS($P8)>=1,1,0),0) -> 0 | R8: =IF($A8="","",IF($A8=$A7,N($R7),1-N($R7))) -> 0
A9: V-2026-10-002 | B9: 46296 | C9: 계약서 | D9: 익명조합 출자금 입금 | E9: 102 | F9: 30000000 | I9: 기업은행 | J9: 사업용계좌 입금 | K9: =IF($B9="","",TEXT($B9,"yyyy-mm")) -> 2026-10 | L9: =IF($E9="","",IFERROR(INDEX(계정과목!$B$6:$B$58,MATCH($E9,계정과목!$A$6:$A$58,0)),"미등록")) -> 보통예금 | M9: =IF($E9="","",IFERROR(INDEX(계정과목!$C$6:$C$58,MATCH($E9,계정과목!$A$6:$A$58,0)),"")) -> 자산 | N9: =IF($E9="","",IFERROR(INDEX(계정과목!$D$6:$D$58,MATCH($E9,계정과목!$A$6:$A$58,0)),"")) -> 해당없음 | O9: =IF($E9="","",IF(COUNTIF(계정과목!$A$6:$A$58,$E9)=0,"미등록","정상")) -> 정상 | P9: =IF($A9="","",ROUND(SUMIFS(전표!$F$7:$F$282,전표!$A$7:$A$282,$A9)-SUMIFS(전표!$G$7:$G$282,전표!$A$7:$A$282,$A9),0)) -> 0 | Q9: =IF(ISNUMBER($P9),IF(ABS($P9)>=1,1,0),0) -> 0 | R9: =IF($A9="","",IF($A9=$A8,N($R8),1-N($R8))) -> 1
A10: V-2026-10-002 | B10: 46296 | C10: 계약서 | D10: 익명조합 출자금 입금 | E10: 241 | G10: 30000000 | I10: 익명조합원 | J10: 5년 원금보장 특약 | K10: =IF($B10="","",TEXT($B10,"yyyy-mm")) -> 2026-10 | L10: =IF($E10="","",IFERROR(INDEX(계정과목!$B$6:$B$58,MATCH($E10,계정과목!$A$6:$A$58,0)),"미등록")) -> 장기차입금 | M10: =IF($E10="","",IFERROR(INDEX(계정과목!$C$6:$C$58,MATCH($E10,계정과목!$A$6:$A$58,0)),"")) -> 부채 | N10: =IF($E10="","",IFERROR(INDEX(계정과목!$D$6:$D$58,MATCH($E10,계정과목!$A$6:$A$58,0)),"")) -> 해당없음 | O10: =IF($E10="","",IF(COUNTIF(계정과목!$A$6:$A$58,$E10)=0,"미등록","정상")) -> 정상 | P10: =IF($A10="","",ROUND(SUMIFS(전표!$F$7:$F$282,전표!$A$7:$A$282,$A10)-SUMIFS(전표!$G$7:$G$282,전표!$A$7:$A$282,$A10),0)) -> 0 | Q10: =IF(ISNUMBER($P10),IF(ABS($P10)>=1,1,0),0) -> 0 | R10: =IF($A10="","",IF($A10=$A9,N($R9),1-N($R9))) -> 1
A11: V-2026-10-003 | B11: 46296 | C11: 세금계산서 | D11: 1년차 시설 사용료 | E11: 510 | F11: 43000000 | H11: =ROUND(F11*0.1, 0) -> 4300000 | I11: 봉화군청 | K11: =IF($B11="","",TEXT($B11,"yyyy-mm")) -> 2026-10 | L11: =IF($E11="","",IFERROR(INDEX(계정과목!$B$6:$B$58,MATCH($E11,계정과목!$A$6:$A$58,0)),"미등록")) -> 임차료 | M11: =IF($E11="","",IFERROR(INDEX(계정과목!$C$6:$C$58,MATCH($E11,계정과목!$A$6:$A$58,0)),"")) -> 비용 | N11: =IF($E11="","",IFERROR(INDEX(계정과목!$D$6:$D$58,MATCH($E11,계정과목!$A$6:$A$58,0)),"")) -> 과세 | O11: =IF($E11="","",IF(COUNTIF(계정과목!$A$6:$A$58,$E11)=0,"미등록","정상")) -> 정상 | P11: =IF($A11="","",ROUND(SUMIFS(전표!$F$7:$F$282,전표!$A$7:$A$282,$A11)-SUMIFS(전표!$G$7:$G$282,전표!$A$7:$A$282,$A11),0)) -> 0 | Q11: =IF(ISNUMBER($P11),IF(ABS($P11)>=1,1,0),0) -> 0 | R11: =IF($A11="","",IF($A11=$A10,N($R10),1-N($R10))) -> 0
A12: V-2026-10-003 | B12: 46296 | C12: 세금계산서 | D12: 1년차 시설 사용료 부가세 | E12: 135 | F12: =ROUND(F11*0.1, 0) -> 4300000 | I12: 봉화군청 | K12: =IF($B12="","",TEXT($B12,"yyyy-mm")) -> 2026-10 | L12: =IF($E12="","",IFERROR(INDEX(계정과목!$B$6:$B$58,MATCH($E12,계정과목!$A$6:$A$58,0)),"미등록")) -> 부가세대급금 | M12: =IF($E12="","",IFERROR(INDEX(계정과목!$C$6:$C$58,MATCH($E12,계정과목!$A$6:$A$58,0)),"")) -> 자산 | N12: =IF($E12="","",IFERROR(INDEX(계정과목!$D$6:$D$58,MATCH($E12,계정과목!$A$6:$A$58,0)),"")) -> 해당없음 | O12: =IF($E12="","",IF(COUNTIF(계정과목!$A$6:$A$58,$E12)=0,"미등록","정상")) -> 정상 | P12: =IF($A12="","",ROUND(SUMIFS(전표!$F$7:$F$282,전표!$A$7:$A$282,$A12)-SUMIFS(전표!$G$7:$G$282,전표!$A$7:$A$282,$A12),0)) -> 0 | Q12: =IF(ISNUMBER($P12),IF(ABS($P12)>=1,1,0),0) -> 0 | R12: =IF($A12="","",IF($A12=$A11,N($R11),1-N($R11))) -> 0
A13: V-2026-10-003 | B13: 46296 | C13: 세금계산서 | D13: 1년차 사용료 미지급금 | E13: 202 | G13: =SUM(F11, F12) -> 47300000 | I13: 봉화군청 | K13: =IF($B13="","",TEXT($B13,"yyyy-mm")) -> 2026-10 | L13: =IF($E13="","",IFERROR(INDEX(계정과목!$B$6:$B$58,MATCH($E13,계정과목!$A$6:$A$58,0)),"미등록")) -> 미지급금 | M13: =IF($E13="","",IFERROR(INDEX(계정과목!$C$6:$C$58,MATCH($E13,계정과목!$A$6:$A$58,0)),"")) -> 부채 | N13: =IF($E13="","",IFERROR(INDEX(계정과목!$D$6:$D$58,MATCH($E13,계정과목!$A$6:$A$58,0)),"")) -> 해당없음 | O13: =IF($E13="","",IF(COUNTIF(계정과목!$A$6:$A$58,$E13)=0,"미등록","정상")) -> 정상 | P13: =IF($A13="","",ROUND(SUMIFS(전표!$F$7:$F$282,전표!$A$7:$A$282,$A13)-SUMIFS(전표!$G$7:$G$282,전표!$A$7:$A$282,$A13),0)) -> 0 | Q13: =IF(ISNUMBER($P13),IF(ABS($P13)>=1,1,0),0) -> 0 | R13: =IF($A13="","",IF($A13=$A12,N($R12),1-N($R12))) -> 0
A14: V-2026-10-004 | B14: 46297 | C14: 기타 | D14: 1년차 시설 사용료 1회차 납부 | E14: 202 | F14: =ROUND(G13/3, 0) -> 15766667 | I14: 봉화군청 | J14: 3회 분납건 | K14: =IF($B14="","",TEXT($B14,"yyyy-mm")) -> 2026-10 | L14: =IF($E14="","",IFERROR(INDEX(계정과목!$B$6:$B$58,MATCH($E14,계정과목!$A$6:$A$58,0)),"미등록")) -> 미지급금 | M14: =IF($E14="","",IFERROR(INDEX(계정과목!$C$6:$C$58,MATCH($E14,계정과목!$A$6:$A$58,0)),"")) -> 부채 | N14: =IF($E14="","",IFERROR(INDEX(계정과목!$D$6:$D$58,MATCH($E14,계정과목!$A$6:$A$58,0)),"")) -> 해당없음 | O14: =IF($E14="","",IF(COUNTIF(계정과목!$A$6:$A$58,$E14)=0,"미등록","정상")) -> 정상 | P14: =IF($A14="","",ROUND(SUMIFS(전표!$F$7:$F$282,전표!$A$7:$A$282,$A14)-SUMIFS(전표!$G$7:$G$282,전표!$A$7:$A$282,$A14),0)) -> 0 | Q14: =IF(ISNUMBER($P14),IF(ABS($P14)>=1,1,0),0) -> 0 | R14: =IF($A14="","",IF($A14=$A13,N($R13),1-N($R13))) -> 1
A15: V-2026-10-004 | B15: 46297 | C15: 기타 | D15: 1년차 시설 사용료 1회차 출금 | E15: 102 | G15: =F14 -> 15766667 | I15: 봉화군청 | J15: 3회 분납건 | K15: =IF($B15="","",TEXT($B15,"yyyy-mm")) -> 2026-10 | L15: =IF($E15="","",IFERROR(INDEX(계정과목!$B$6:$B$58,MATCH($E15,계정과목!$A$6:$A$58,0)),"미등록")) -> 보통예금 | M15: =IF($E15="","",IFERROR(INDEX(계정과목!$C$6:$C$58,MATCH($E15,계정과목!$A$6:$A$58,0)),"")) -> 자산 | N15: =IF($E15="","",IFERROR(INDEX(계정과목!$D$6:$D$58,MATCH($E15,계정과목!$A$6:$A$58,0)),"")) -> 해당없음 | O15: =IF($E15="","",IF(COUNTIF(계정과목!$A$6:$A$58,$E15)=0,"미등록","정상")) -> 정상 | P15: =IF($A15="","",ROUND(SUMIFS(전표!$F$7:$F$282,전표!$A$7:$A$282,$A15)-SUMIFS(전표!$G$7:$G$282,전표!$A$7:$A$282,$A15),0)) -> 0 | Q15: =IF(ISNUMBER($P15),IF(ABS($P15)>=1,1,0),0) -> 0 | R15: =IF($A15="","",IF($A15=$A14,N($R14),1-N($R14))) -> 1
A16: V-2026-10-005 | B16: 46298 | C16: 현금영수증 | D16: 일일매출 현금입금 | E16: 101 | F16: 7600 | I16: 개인고객 | J16: 현금시재 | K16: =IF($B16="","",TEXT($B16,"yyyy-mm")) -> 2026-10 | L16: =IF($E16="","",IFERROR(INDEX(계정과목!$B$6:$B$58,MATCH($E16,계정과목!$A$6:$A$58,0)),"미등록")) -> 현금 | M16: =IF($E16="","",IFERROR(INDEX(계정과목!$C$6:$C$58,MATCH($E16,계정과목!$A$6:$A$58,0)),"")) -> 자산 | N16: =IF($E16="","",IFERROR(INDEX(계정과목!$D$6:$D$58,MATCH($E16,계정과목!$A$6:$A$58,0)),"")) -> 해당없음 | O16: =IF($E16="","",IF(COUNTIF(계정과목!$A$6:$A$58,$E16)=0,"미등록","정상")) -> 정상 | P16: =IF($A16="","",ROUND(SUMIFS(전표!$F$7:$F$282,전표!$A$7:$A$282,$A16)-SUMIFS(전표!$G$7:$G$282,전표!$A$7:$A$282,$A16),0)) -> 0 | Q16: =IF(ISNUMBER($P16),IF(ABS($P16)>=1,1,0),0) -> 0 | R16: =IF($A16="","",IF($A16=$A15,N($R15),1-N($R15))) -> 0
A17: V-2026-10-005 | B17: 46298 | C17: 기타 | D17: 일일매출 상품권수납 | E17: 104 | F17: 30000 | I17: 봉화군청 | J17: 봉화사랑상품권 | K17: =IF($B17="","",TEXT($B17,"yyyy-mm")) -> 2026-10 | L17: =IF($E17="","",IFERROR(INDEX(계정과목!$B$6:$B$58,MATCH($E17,계정과목!$A$6:$A$58,0)),"미등록")) -> 상품권 | M17: =IF($E17="","",IFERROR(INDEX(계정과목!$C$6:$C$58,MATCH($E17,계정과목!$A$6:$A$58,0)),"")) -> 자산 | N17: =IF($E17="","",IFERROR(INDEX(계정과목!$D$6:$D$58,MATCH($E17,계정과목!$A$6:$A$58,0)),"")) -> 해당없음 | O17: =IF($E17="","",IF(COUNTIF(계정과목!$A$6:$A$58,$E17)=0,"미등록","정상")) -> 정상 | P17: =IF($A17="","",ROUND(SUMIFS(전표!$F$7:$F$282,전표!$A$7:$A$282,$A17)-SUMIFS(전표!$G$7:$G$282,전표!$A$7:$A$282,$A17),0)) -> 0 | Q17: =IF(ISNUMBER($P17),IF(ABS($P17)>=1,1,0),0) -> 0 | R17: =IF($A17="","",IF($A17=$A16,N($R16),1-N($R16))) -> 0
A18: V-2026-10-005 | B18: 46298 | C18: 카드전표 | D18: 일일매출 카드결제 | E18: 103 | F18: 49000 | I18: 카드사 | J18: 미정산금 | K18: =IF($B18="","",TEXT($B18,"yyyy-mm")) -> 2026-10 | L18: =IF($E18="","",IFERROR(INDEX(계정과목!$B$6:$B$58,MATCH($E18,계정과목!$A$6:$A$58,0)),"미등록")) -> 카드매출미정산금 | M18: =IF($E18="","",IFERROR(INDEX(계정과목!$C$6:$C$58,MATCH($E18,계정과목!$A$6:$A$58,0)),"")) -> 자산 | N18: =IF($E18="","",IFERROR(INDEX(계정과목!$D$6:$D$58,MATCH($E18,계정과목!$A$6:$A$58,0)),"")) -> 해당없음 | O18: =IF($E18="","",IF(COUNTIF(계정과목!$A$6:$A$58,$E18)=0,"미등록","정상")) -> 정상 | P18: =IF($A18="","",ROUND(SUMIFS(전표!$F$7:$F$282,전표!$A$7:$A$282,$A18)-SUMIFS(전표!$G$7:$G$282,전표!$A$7:$A$282,$A18),0)) -> 0 | Q18: =IF(ISNUMBER($P18),IF(ABS($P18)>=1,1,0),0) -> 0 | R18: =IF($A18="","",IF($A18=$A17,N($R17),1-N($R17))) -> 0
A19: V-2026-10-005 | B19: 46298 | C19: 기타 | D19: 일일매출 부가세 예수 | E19: 220 | G19: =ROUND((F16+F18+F17)/11, 0) -> 7873 | I19: 세무서 | J19: 부가세 10% | K19: =IF($B19="","",TEXT($B19,"yyyy-mm")) -> 2026-10 | L19: =IF($E19="","",IFERROR(INDEX(계정과목!$B$6:$B$58,MATCH($E19,계정과목!$A$6:$A$58,0)),"미등록")) -> 부가세예수금 | M19: =IF($E19="","",IFERROR(INDEX(계정과목!$C$6:$C$58,MATCH($E19,계정과목!$A$6:$A$58,0)),"")) -> 부채 | N19: =IF($E19="","",IFERROR(INDEX(계정과목!$D$6:$D$58,MATCH($E19,계정과목!$A$6:$A$58,0)),"")) -> 해당없음 | O19: =IF($E19="","",IF(COUNTIF(계정과목!$A$6:$A$58,$E19)=0,"미등록","정상")) -> 정상 | P19: =IF($A19="","",ROUND(SUMIFS(전표!$F$7:$F$282,전표!$A$7:$A$282,$A19)-SUMIFS(전표!$G$7:$G$282,전표!$A$7:$A$282,$A19),0)) -> 0 | Q19: =IF(ISNUMBER($P19),IF(ABS($P19)>=1,1,0),0) -> 0 | R19: =IF($A19="","",IF($A19=$A18,N($R18),1-N($R18))) -> 0
A20: V-2026-10-005 | B20: 46298 | C20: 카드전표 | D20: 놀이동 매출 | E20: 401 | G20: =ROUND(73600/1.1, 0) -> 66909 | I20: 개인고객 | J20: 공급가액 | K20: =IF($B20="","",TEXT($B20,"yyyy-mm")) -> 2026-10 | L20: =IF($E20="","",IFERROR(INDEX(계정과목!$B$6:$B$58,MATCH($E20,계정과목!$A$6:$A$58,0)),"미등록")) -> 체험·입장료수입 | M20: =IF($E20="","",IFERROR(INDEX(계정과목!$C$6:$C$58,MATCH($E20,계정과목!$A$6:$A$58,0)),"")) -> 수익 | N20: =IF($E20="","",IFERROR(INDEX(계정과목!$D$6:$D$58,MATCH($E20,계정과목!$A$6:$A$58,0)),"")) -> 과세 | O20: =IF($E20="","",IF(COUNTIF(계정과목!$A$6:$A$58,$E20)=0,"미등록","정상")) -> 정상 | P20: =IF($A20="","",ROUND(SUMIFS(전표!$F$7:$F$282,전표!$A$7:$A$282,$A20)-SUMIFS(전표!$G$7:$G$282,전표!$A$7:$A$282,$A20),0)) -> 0 | Q20: =IF(ISNUMBER($P20),IF(ABS($P20)>=1,1,0),0) -> 0 | R20: =IF($A20="","",IF($A20=$A19,N($R19),1-N($R19))) -> 0
A21: V-2026-10-005 | B21: 46298 | C21: 카드전표 | D21: 사무동 매출 | E21: 403 | G21: =ROUND(13000/1.1, 0) -> 11818 | I21: 카페 | J21: 공급가액 | K21: =IF($B21="","",TEXT($B21,"yyyy-mm")) -> 2026-10 | L21: =IF($E21="","",IFERROR(INDEX(계정과목!$B$6:$B$58,MATCH($E21,계정과목!$A$6:$A$58,0)),"미등록")) -> 매점매출 | M21: =IF($E21="","",IFERROR(INDEX(계정과목!$C$6:$C$58,MATCH($E21,계정과목!$A$6:$A$58,0)),"")) -> 수익 | N21: =IF($E21="","",IFERROR(INDEX(계정과목!$D$6:$D$58,MATCH($E21,계정과목!$A$6:$A$58,0)),"")) -> 과세 | O21: =IF($E21="","",IF(COUNTIF(계정과목!$A$6:$A$58,$E21)=0,"미등록","정상")) -> 정상 | P21: =IF($A21="","",ROUND(SUMIFS(전표!$F$7:$F$282,전표!$A$7:$A$282,$A21)-SUMIFS(전표!$G$7:$G$282,전표!$A$7:$A$282,$A21),0)) -> 0 | Q21: =IF(ISNUMBER($P21),IF(ABS($P21)>=1,1,0),0) -> 0 | R21: =IF($A21="","",IF($A21=$A20,N($R20),1-N($R20))) -> 0
A22: V-2026-10-006 | B22: 46299 | C22: 세금계산서 | D22: 시설 전체 대관료 입금 | E22: 102 | F22: 3300000 | I22: 기업은행 | J22: 봉화군 어린이집 연합회 | K22: =IF($B22="","",TEXT($B22,"yyyy-mm")) -> 2026-10 | L22: =IF($E22="","",IFERROR(INDEX(계정과목!$B$6:$B$58,MATCH($E22,계정과목!$A$6:$A$58,0)),"미등록")) -> 보통예금 | M22: =IF($E22="","",IFERROR(INDEX(계정과목!$C$6:$C$58,MATCH($E22,계정과목!$A$6:$A$58,0)),"")) -> 자산 | N22: =IF($E22="","",IFERROR(INDEX(계정과목!$D$6:$D$58,MATCH($E22,계정과목!$A$6:$A$58,0)),"")) -> 해당없음 | O22: =IF($E22="","",IF(COUNTIF(계정과목!$A$6:$A$58,$E22)=0,"미등록","정상")) -> 정상 | P22: =IF($A22="","",ROUND(SUMIFS(전표!$F$7:$F$282,전표!$A$7:$A$282,$A22)-SUMIFS(전표!$G$7:$G$282,전표!$A$7:$A$282,$A22),0)) -> 0 | Q22: =IF(ISNUMBER($P22),IF(ABS($P22)>=1,1,0),0) -> 0 | R22: =IF($A22="","",IF($A22=$A21,N($R21),1-N($R21))) -> 1
A23: V-2026-10-006 | B23: 46299 | C23: 세금계산서 | D23: 시설 전체 대관 매출 | E23: 401 | G23: 3000000 | H23: 300000 | I23: 봉화군 어린이집 연합회 | J23: 공급가액 | K23: =IF($B23="","",TEXT($B23,"yyyy-mm")) -> 2026-10 | L23: =IF($E23="","",IFERROR(INDEX(계정과목!$B$6:$B$58,MATCH($E23,계정과목!$A$6:$A$58,0)),"미등록")) -> 체험·입장료수입 | M23: =IF($E23="","",IFERROR(INDEX(계정과목!$C$6:$C$58,MATCH($E23,계정과목!$A$6:$A$58,0)),"")) -> 수익 | N23: =IF($E23="","",IFERROR(INDEX(계정과목!$D$6:$D$58,MATCH($E23,계정과목!$A$6:$A$58,0)),"")) -> 과세 | O23: =IF($E23="","",IF(COUNTIF(계정과목!$A$6:$A$58,$E23)=0,"미등록","정상")) -> 정상 | P23: =IF($A23="","",ROUND(SUMIFS(전표!$F$7:$F$282,전표!$A$7:$A$282,$A23)-SUMIFS(전표!$G$7:$G$282,전표!$A$7:$A$282,$A23),0)) -> 0 | Q23: =IF(ISNUMBER($P23),IF(ABS($P23)>=1,1,0),0) -> 0 | R23: =IF($A23="","",IF($A23=$A22,N($R22),1-N($R22))) -> 1
A24: V-2026-10-006 | B24: 46299 | C24: 세금계산서 | D24: 일일매출 부가세 예수 | E24: 220 | G24: 300000 | I24: 세무서 | J24: 부가세 10% | K24: =IF($B24="","",TEXT($B24,"yyyy-mm")) -> 2026-10 | L24: =IF($E24="","",IFERROR(INDEX(계정과목!$B$6:$B$58,MATCH($E24,계정과목!$A$6:$A$58,0)),"미등록")) -> 부가세예수금 | M24: =IF($E24="","",IFERROR(INDEX(계정과목!$C$6:$C$58,MATCH($E24,계정과목!$A$6:$A$58,0)),"")) -> 부채 | N24: =IF($E24="","",IFERROR(INDEX(계정과목!$D$6:$D$58,MATCH($E24,계정과목!$A$6:$A$58,0)),"")) -> 해당없음 | O24: =IF($E24="","",IF(COUNTIF(계정과목!$A$6:$A$58,$E24)=0,"미등록","정상")) -> 정상 | P24: =IF($A24="","",ROUND(SUMIFS(전표!$F$7:$F$282,전표!$A$7:$A$282,$A24)-SUMIFS(전표!$G$7:$G$282,전표!$A$7:$A$282,$A24),0)) -> 0 | Q24: =IF(ISNUMBER($P24),IF(ABS($P24)>=1,1,0),0) -> 0 | R24: =IF($A24="","",IF($A24=$A23,N($R23),1-N($R23))) -> 1
A25: V-2026-10-007 | B25: 46300 | C25: 카드전표 | D25: 카페 우유 구입 | E25: 516 | F25: 50000 | H25: 5000 | I25: 하나로마트 | J25: 재료비 | K25: =IF($B25="","",TEXT($B25,"yyyy-mm")) -> 2026-10 | L25: =IF($E25="","",IFERROR(INDEX(계정과목!$B$6:$B$58,MATCH($E25,계정과목!$A$6:$A$58,0)),"미등록")) -> 소모품비 | M25: =IF($E25="","",IFERROR(INDEX(계정과목!$C$6:$C$58,MATCH($E25,계정과목!$A$6:$A$58,0)),"")) -> 비용 | N25: =IF($E25="","",IFERROR(INDEX(계정과목!$D$6:$D$58,MATCH($E25,계정과목!$A$6:$A$58,0)),"")) -> 과세 | O25: =IF($E25="","",IF(COUNTIF(계정과목!$A$6:$A$58,$E25)=0,"미등록","정상")) -> 정상 | P25: =IF($A25="","",ROUND(SUMIFS(전표!$F$7:$F$282,전표!$A$7:$A$282,$A25)-SUMIFS(전표!$G$7:$G$282,전표!$A$7:$A$282,$A25),0)) -> 0 | Q25: =IF(ISNUMBER($P25),IF(ABS($P25)>=1,1,0),0) -> 0 | R25: =IF($A25="","",IF($A25=$A24,N($R24),1-N($R24))) -> 0
A26: V-2026-10-007 | B26: 46300 | C26: 카드전표 | D26: 카페 식자재 부가세 | E26: 135 | F26: 5000 | I26: 하나로마트 | J26: 매입세액 | K26: =IF($B26="","",TEXT($B26,"yyyy-mm")) -> 2026-10 | L26: =IF($E26="","",IFERROR(INDEX(계정과목!$B$6:$B$58,MATCH($E26,계정과목!$A$6:$A$58,0)),"미등록")) -> 부가세대급금 | M26: =IF($E26="","",IFERROR(INDEX(계정과목!$C$6:$C$58,MATCH($E26,계정과목!$A$6:$A$58,0)),"")) -> 자산 | N26: =IF($E26="","",IFERROR(INDEX(계정과목!$D$6:$D$58,MATCH($E26,계정과목!$A$6:$A$58,0)),"")) -> 해당없음 | O26: =IF($E26="","",IF(COUNTIF(계정과목!$A$6:$A$58,$E26)=0,"미등록","정상")) -> 정상 | P26: =IF($A26="","",ROUND(SUMIFS(전표!$F$7:$F$282,전표!$A$7:$A$282,$A26)-SUMIFS(전표!$G$7:$G$282,전표!$A$7:$A$282,$A26),0)) -> 0 | Q26: =IF(ISNUMBER($P26),IF(ABS($P26)>=1,1,0),0) -> 0 | R26: =IF($A26="","",IF($A26=$A25,N($R25),1-N($R25))) -> 0
A27: V-2026-10-007 | B27: 46300 | C27: 카드전표 | D27: 마트 법인카드 결제 | E27: 202 | G27: 55000 | I27: 농협카드 | J27: 미지급금 | K27: =IF($B27="","",TEXT($B27,"yyyy-mm")) -> 2026-10 | L27: =IF($E27="","",IFERROR(INDEX(계정과목!$B$6:$B$58,MATCH($E27,계정과목!$A$6:$A$58,0)),"미등록")) -> 미지급금 | M27: =IF($E27="","",IFERROR(INDEX(계정과목!$C$6:$C$58,MATCH($E27,계정과목!$A$6:$A$58,0)),"")) -> 부채 | N27: =IF($E27="","",IFERROR(INDEX(계정과목!$D$6:$D$58,MATCH($E27,계정과목!$A$6:$A$58,0)),"")) -> 해당없음 | O27: =IF($E27="","",IF(COUNTIF(계정과목!$A$6:$A$58,$E27)=0,"미등록","정상")) -> 정상 | P27: =IF($A27="","",ROUND(SUMIFS(전표!$F$7:$F$282,전표!$A$7:$A$282,$A27)-SUMIFS(전표!$G$7:$G$282,전표!$A$7:$A$282,$A27),0)) -> 0 | Q27: =IF(ISNUMBER($P27),IF(ABS($P27)>=1,1,0),0) -> 0 | R27: =IF($A27="","",IF($A27=$A26,N($R26),1-N($R26))) -> 0
A28: V-2026-10-008 | B28: 46301 | C28: 기타 | D28: 10/6 일일매출 현금시재 입금 | E28: 101 | F28: 40000 | I28: 개인고객 | J28: 봉화군민 기본권(현금) | K28: =IF($B28="","",TEXT($B28,"yyyy-mm")) -> 2026-10 | L28: =IF($E28="","",IFERROR(INDEX(계정과목!$B$6:$B$58,MATCH($E28,계정과목!$A$6:$A$58,0)),"미등록")) -> 현금 | M28: =IF($E28="","",IFERROR(INDEX(계정과목!$C$6:$C$58,MATCH($E28,계정과목!$A$6:$A$58,0)),"")) -> 자산 | N28: =IF($E28="","",IFERROR(INDEX(계정과목!$D$6:$D$58,MATCH($E28,계정과목!$A$6:$A$58,0)),"")) -> 해당없음 | O28: =IF($E28="","",IF(COUNTIF(계정과목!$A$6:$A$58,$E28)=0,"미등록","정상")) -> 정상 | P28: =IF($A28="","",ROUND(SUMIFS(전표!$F$7:$F$282,전표!$A$7:$A$282,$A28)-SUMIFS(전표!$G$7:$G$282,전표!$A$7:$A$282,$A28),0)) -> 0 | Q28: =IF(ISNUMBER($P28),IF(ABS($P28)>=1,1,0),0) -> 0 | R28: =IF($A28="","",IF($A28=$A27,N($R27),1-N($R27))) -> 1
A29: V-2026-10-008 | B29: 46301 | C29: 카드전표 | D29: 10/6 일일매출 카드결제 | E29: 103 | F29: 44450 | I29: 토스카드사 | J29: 카페+영주종합권(카드) | K29: =IF($B29="","",TEXT($B29,"yyyy-mm")) -> 2026-10 | L29: =IF($E29="","",IFERROR(INDEX(계정과목!$B$6:$B$58,MATCH($E29,계정과목!$A$6:$A$58,0)),"미등록")) -> 카드매출미정산금 | M29: =IF($E29="","",IFERROR(INDEX(계정과목!$C$6:$C$58,MATCH($E29,계정과목!$A$6:$A$58,0)),"")) -> 자산 | N29: =IF($E29="","",IFERROR(INDEX(계정과목!$D$6:$D$58,MATCH($E29,계정과목!$A$6:$A$58,0)),"")) -> 해당없음 | O29: =IF($E29="","",IF(COUNTIF(계정과목!$A$6:$A$58,$E29)=0,"미등록","정상")) -> 정상 | P29: =IF($A29="","",ROUND(SUMIFS(전표!$F$7:$F$282,전표!$A$7:$A$282,$A29)-SUMIFS(전표!$G$7:$G$282,전표!$A$7:$A$282,$A29),0)) -> 0 | Q29: =IF(ISNUMBER($P29),IF(ABS($P29)>=1,1,0),0) -> 0 | R29: =IF($A29="","",IF($A29=$A28,N($R28),1-N($R28))) -> 1
A30: V-2026-10-008 | B30: 46301 | C30: 카드전표 | D30: 10/6 놀이동 입장권 매출 | E30: 401 | G30: 60000 | H30: 6000 | I30: 개인고객 | J30: 공급가액(봉화+영주) | K30: =IF($B30="","",TEXT($B30,"yyyy-mm")) -> 2026-10 | L30: =IF($E30="","",IFERROR(INDEX(계정과목!$B$6:$B$58,MATCH($E30,계정과목!$A$6:$A$58,0)),"미등록")) -> 체험·입장료수입 | M30: =IF($E30="","",IFERROR(INDEX(계정과목!$C$6:$C$58,MATCH($E30,계정과목!$A$6:$A$58,0)),"")) -> 수익 | N30: =IF($E30="","",IFERROR(INDEX(계정과목!$D$6:$D$58,MATCH($E30,계정과목!$A$6:$A$58,0)),"")) -> 과세 | O30: =IF($E30="","",IF(COUNTIF(계정과목!$A$6:$A$58,$E30)=0,"미등록","정상")) -> 정상 | P30: =IF($A30="","",ROUND(SUMIFS(전표!$F$7:$F$282,전표!$A$7:$A$282,$A30)-SUMIFS(전표!$G$7:$G$282,전표!$A$7:$A$282,$A30),0)) -> 0 | Q30: =IF(ISNUMBER($P30),IF(ABS($P30)>=1,1,0),0) -> 0 | R30: =IF($A30="","",IF($A30=$A29,N($R29),1-N($R29))) -> 1
A31: V-2026-10-008 | B31: 46301 | C31: 카드전표 | D31: 10/6 카페 식음료 매출 | E31: 403 | G31: 16773 | H31: 1677 | I31: 개인고객 | J31: 공급가액(10%할인) | K31: =IF($B31="","",TEXT($B31,"yyyy-mm")) -> 2026-10 | L31: =IF($E31="","",IFERROR(INDEX(계정과목!$B$6:$B$58,MATCH($E31,계정과목!$A$6:$A$58,0)),"미등록")) -> 매점매출 | M31: =IF($E31="","",IFERROR(INDEX(계정과목!$C$6:$C$58,MATCH($E31,계정과목!$A$6:$A$58,0)),"")) -> 수익 | N31: =IF($E31="","",IFERROR(INDEX(계정과목!$D$6:$D$58,MATCH($E31,계정과목!$A$6:$A$58,0)),"")) -> 과세 | O31: =IF($E31="","",IF(COUNTIF(계정과목!$A$6:$A$58,$E31)=0,"미등록","정상")) -> 정상 | P31: =IF($A31="","",ROUND(SUMIFS(전표!$F$7:$F$282,전표!$A$7:$A$282,$A31)-SUMIFS(전표!$G$7:$G$282,전표!$A$7:$A$282,$A31),0)) -> 0 | Q31: =IF(ISNUMBER($P31),IF(ABS($P31)>=1,1,0),0) -> 0 | R31: =IF($A31="","",IF($A31=$A30,N($R30),1-N($R30))) -> 1
A32: V-2026-10-008 | B32: 46301 | C32: 기타 | D32: 10/6 일일매출 부가세 예수 | E32: 220 | G32: 7677 | I32: 세무서 | J32: 부가세 10% | K32: =IF($B32="","",TEXT($B32,"yyyy-mm")) -> 2026-10 | L32: =IF($E32="","",IFERROR(INDEX(계정과목!$B$6:$B$58,MATCH($E32,계정과목!$A$6:$A$58,0)),"미등록")) -> 부가세예수금 | M32: =IF($E32="","",IFERROR(INDEX(계정과목!$C$6:$C$58,MATCH($E32,계정과목!$A$6:$A$58,0)),"")) -> 부채 | N32: =IF($E32="","",IFERROR(INDEX(계정과목!$D$6:$D$58,MATCH($E32,계정과목!$A$6:$A$58,0)),"")) -> 해당없음 | O32: =IF($E32="","",IF(COUNTIF(계정과목!$A$6:$A$58,$E32)=0,"미등록","정상")) -> 정상 | P32: =IF($A32="","",ROUND(SUMIFS(전표!$F$7:$F$282,전표!$A$7:$A$282,$A32)-SUMIFS(전표!$G$7:$G$282,전표!$A$7:$A$282,$A32),0)) -> 0 | Q32: =IF(ISNUMBER($P32),IF(ABS($P32)>=1,1,0),0) -> 0 | R32: =IF($A32="","",IF($A32=$A31,N($R31),1-N($R31))) -> 1
K33: =IF($B33="","",TEXT($B33,"yyyy-mm")) | L33: =IF($E33="","",IFERROR(INDEX(계정과목!$B$6:$B$58,MATCH($E33,계정과목!$A$6:$A$58,0)),"미등록")) | M33: =IF($E33="","",IFERROR(INDEX(계정과목!$C$6:$C$58,MATCH($E33,계정과목!$A$6:$A$58,0)),"")) | N33: =IF($E33="","",IFERROR(INDEX(계정과목!$D$6:$D$58,MATCH($E33,계정과목!$A$6:$A$58,0)),"")) | O33: =IF($E33="","",IF(COUNTIF(계정과목!$A$6:$A$58,$E33)=0,"미등록","정상")) | P33: =IF($A33="","",ROUND(SUMIFS(전표!$F$7:$F$282,전표!$A$7:$A$282,$A33)-SUMIFS(전표!$G$7:$G$282,전표!$A$7:$A$282,$A33),0)) | Q33: =IF(ISNUMBER($P33),IF(ABS($P33)>=1,1,0),0) -> 0 | R33: =IF($A33="","",IF($A33=$A32,N($R32),1-N($R32)))
K34: =IF($B34="","",TEXT($B34,"yyyy-mm")) | L34: =IF($E34="","",IFERROR(INDEX(계정과목!$B$6:$B$58,MATCH($E34,계정과목!$A$6:$A$58,0)),"미등록")) | M34: =IF($E34="","",IFERROR(INDEX(계정과목!$C$6:$C$58,MATCH($E34,계정과목!$A$6:$A$58,0)),"")) | N34: =IF($E34="","",IFERROR(INDEX(계정과목!$D$6:$D$58,MATCH($E34,계정과목!$A$6:$A$58,0)),"")) | O34: =IF($E34="","",IF(COUNTIF(계정과목!$A$6:$A$58,$E34)=0,"미등록","정상")) | P34: =IF($A34="","",ROUND(SUMIFS(전표!$F$7:$F$282,전표!$A$7:$A$282,$A34)-SUMIFS(전표!$G$7:$G$282,전표!$A$7:$A$282,$A34),0)) | Q34: =IF(ISNUMBER($P34),IF(ABS($P34)>=1,1,0),0) -> 0 | R34: =IF($A34="","",IF($A34=$A33,N($R33),1-N($R33)))
K35: =IF($B35="","",TEXT($B35,"yyyy-mm")) | L35: =IF($E35="","",IFERROR(INDEX(계정과목!$B$6:$B$58,MATCH($E35,계정과목!$A$6:$A$58,0)),"미등록")) | M35: =IF($E35="","",IFERROR(INDEX(계정과목!$C$6:$C$58,MATCH($E35,계정과목!$A$6:$A$58,0)),"")) | N35: =IF($E35="","",IFERROR(INDEX(계정과목!$D$6:$D$58,MATCH($E35,계정과목!$A$6:$A$58,0)),"")) | O35: =IF($E35="","",IF(COUNTIF(계정과목!$A$6:$A$58,$E35)=0,"미등록","정상")) | P35: =IF($A35="","",ROUND(SUMIFS(전표!$F$7:$F$282,전표!$A$7:$A$282,$A35)-SUMIFS(전표!$G$7:$G$282,전표!$A$7:$A$282,$A35),0)) | Q35: =IF(ISNUMBER($P35),IF(ABS($P35)>=1,1,0),0) -> 0 | R35: =IF($A35="","",IF($A35=$A34,N($R34),1-N($R34)))
K36: =IF($B36="","",TEXT($B36,"yyyy-mm")) | L36: =IF($E36="","",IFERROR(INDEX(계정과목!$B$6:$B$58,MATCH($E36,계정과목!$A$6:$A$58,0)),"미등록")) | M36: =IF($E36="","",IFERROR(INDEX(계정과목!$C$6:$C$58,MATCH($E36,계정과목!$A$6:$A$58,0)),"")) | N36: =IF($E36="","",IFERROR(INDEX(계정과목!$D$6:$D$58,MATCH($E36,계정과목!$A$6:$A$58,0)),"")) | O36: =IF($E36="","",IF(COUNTIF(계정과목!$A$6:$A$58,$E36)=0,"미등록","정상")) | P36: =IF($A36="","",ROUND(SUMIFS(전표!$F$7:$F$282,전표!$A$7:$A$282,$A36)-SUMIFS(전표!$G$7:$G$282,전표!$A$7:$A$282,$A36),0)) | Q36: =IF(ISNUMBER($P36),IF(ABS($P36)>=1,1,0),0) -> 0 | R36: =IF($A36="","",IF($A36=$A35,N($R35),1-N($R35)))
K37: =IF($B37="","",TEXT($B37,"yyyy-mm")) | L37: =IF($E37="","",IFERROR(INDEX(계정과목!$B$6:$B$58,MATCH($E37,계정과목!$A$6:$A$58,0)),"미등록")) | M37: =IF($E37="","",IFERROR(INDEX(계정과목!$C$6:$C$58,MATCH($E37,계정과목!$A$6:$A$58,0)),"")) | N37: =IF($E37="","",IFERROR(INDEX(계정과목!$D$6:$D$58,MATCH($E37,계정과목!$A$6:$A$58,0)),"")) | O37: =IF($E37="","",IF(COUNTIF(계정과목!$A$6:$A$58,$E37)=0,"미등록","정상")) | P37: =IF($A37="","",ROUND(SUMIFS(전표!$F$7:$F$282,전표!$A$7:$A$282,$A37)-SUMIFS(전표!$G$7:$G$282,전표!$A$7:$A$282,$A37),0)) | Q37: =IF(ISNUMBER($P37),IF(ABS($P37)>=1,1,0),0) -> 0 | R37: =IF($A37="","",IF($A37=$A36,N($R36),1-N($R36)))
K38: =IF($B38="","",TEXT($B38,"yyyy-mm")) | L38: =IF($E38="","",IFERROR(INDEX(계정과목!$B$6:$B$58,MATCH($E38,계정과목!$A$6:$A$58,0)),"미등록")) | M38: =IF($E38="","",IFERROR(INDEX(계정과목!$C$6:$C$58,MATCH($E38,계정과목!$A$6:$A$58,0)),"")) | N38: =IF($E38="","",IFERROR(INDEX(계정과목!$D$6:$D$58,MATCH($E38,계정과목!$A$6:$A$58,0)),"")) | O38: =IF($E38="","",IF(COUNTIF(계정과목!$A$6:$A$58,$E38)=0,"미등록","정상")) | P38: =IF($A38="","",ROUND(SUMIFS(전표!$F$7:$F$282,전표!$A$7:$A$282,$A38)-SUMIFS(전표!$G$7:$G$282,전표!$A$7:$A$282,$A38),0)) | Q38: =IF(ISNUMBER($P38),IF(ABS($P38)>=1,1,0),0) -> 0 | R38: =IF($A38="","",IF($A38=$A37,N($R37),1-N($R37)))
K39: =IF($B39="","",TEXT($B39,"yyyy-mm")) | L39: =IF($E39="","",IFERROR(INDEX(계정과목!$B$6:$B$58,MATCH($E39,계정과목!$A$6:$A$58,0)),"미등록")) | M39: =IF($E39="","",IFERROR(INDEX(계정과목!$C$6:$C$58,MATCH($E39,계정과목!$A$6:$A$58,0)),"")) | N39: =IF($E39="","",IFERROR(INDEX(계정과목!$D$6:$D$58,MATCH($E39,계정과목!$A$6:$A$58,0)),"")) | O39: =IF($E39="","",IF(COUNTIF(계정과목!$A$6:$A$58,$E39)=0,"미등록","정상")) | P39: =IF($A39="","",ROUND(SUMIFS(전표!$F$7:$F$282,전표!$A$7:$A$282,$A39)-SUMIFS(전표!$G$7:$G$282,전표!$A$7:$A$282,$A39),0)) | Q39: =IF(ISNUMBER($P39),IF(ABS($P39)>=1,1,0),0) -> 0 | R39: =IF($A39="","",IF($A39=$A38,N($R38),1-N($R38)))
K40: =IF($B40="","",TEXT($B40,"yyyy-mm")) | L40: =IF($E40="","",IFERROR(INDEX(계정과목!$B$6:$B$58,MATCH($E40,계정과목!$A$6:$A$58,0)),"미등록")) | M40: =IF($E40="","",IFERROR(INDEX(계정과목!$C$6:$C$58,MATCH($E40,계정과목!$A$6:$A$58,0)),"")) | N40: =IF($E40="","",IFERROR(INDEX(계정과목!$D$6:$D$58,MATCH($E40,계정과목!$A$6:$A$58,0)),"")) | O40: =IF($E40="","",IF(COUNTIF(계정과목!$A$6:$A$58,$E40)=0,"미등록","정상")) | P40: =IF($A40="","",ROUND(SUMIFS(전표!$F$7:$F$282,전표!$A$7:$A$282,$A40)-SUMIFS(전표!$G$7:$G$282,전표!$A$7:$A$282,$A40),0)) | Q40: =IF(ISNUMBER($P40),IF(ABS($P40)>=1,1,0),0) -> 0 | R40: =IF($A40="","",IF($A40=$A39,N($R39),1-N($R39)))
K41: =IF($B41="","",TEXT($B41,"yyyy-mm")) | L41: =IF($E41="","",IFERROR(INDEX(계정과목!$B$6:$B$58,MATCH($E41,계정과목!$A$6:$A$58,0)),"미등록")) | M41: =IF($E41="","",IFERROR(INDEX(계정과목!$C$6:$C$58,MATCH($E41,계정과목!$A$6:$A$58,0)),"")) | N41: =IF($E41="","",IFERROR(INDEX(계정과목!$D$6:$D$58,MATCH($E41,계정과목!$A$6:$A$58,0)),"")) | O41: =IF($E41="","",IF(COUNTIF(계정과목!$A$6:$A$58,$E41)=0,"미등록","정상")) | P41: =IF($A41="","",ROUND(SUMIFS(전표!$F$7:$F$282,전표!$A$7:$A$282,$A41)-SUMIFS(전표!$G$7:$G$282,전표!$A$7:$A$282,$A41),0)) | Q41: =IF(ISNUMBER($P41),IF(ABS($P41)>=1,1,0),0) -> 0 | R41: =IF($A41="","",IF($A41=$A40,N($R40),1-N($R40)))
K42: =IF($B42="","",TEXT($B42,"yyyy-mm")) | L42: =IF($E42="","",IFERROR(INDEX(계정과목!$B$6:$B$58,MATCH($E42,계정과목!$A$6:$A$58,0)),"미등록")) | M42: =IF($E42="","",IFERROR(INDEX(계정과목!$C$6:$C$58,MATCH($E42,계정과목!$A$6:$A$58,0)),"")) | N42: =IF($E42="","",IFERROR(INDEX(계정과목!$D$6:$D$58,MATCH($E42,계정과목!$A$6:$A$58,0)),"")) | O42: =IF($E42="","",IF(COUNTIF(계정과목!$A$6:$A$58,$E42)=0,"미등록","정상")) | P42: =IF($A42="","",ROUND(SUMIFS(전표!$F$7:$F$282,전표!$A$7:$A$282,$A42)-SUMIFS(전표!$G$7:$G$282,전표!$A$7:$A$282,$A42),0)) | Q42: =IF(ISNUMBER($P42),IF(ABS($P42)>=1,1,0),0) -> 0 | R42: =IF($A42="","",IF($A42=$A41,N($R41),1-N($R41)))
...

Sheet 계정과목
A2: 계정과목
A3: 유형은 자산·부채·자본·수익·비용, 부가세구분은 과세·면세·불공제·해당없음 중 하나입니다.
A5: 코드 | B5: 계정명 | C5: 유형 | D5: 부가세구분
A6: 101 | B6: 현금 | C6: 자산 | D6: 해당없음
A7: 102 | B7: 보통예금 | C7: 자산 | D7: 해당없음
A8: 103 | B8: 카드매출미정산금 | C8: 자산 | D8: 해당없음
A9: 104 | B9: 상품권 | C9: 자산 | D9: 해당없음
A10: 120 | B10: 외상매출금 | C10: 자산 | D10: 해당없음
A11: 135 | B11: 부가세대급금 | C11: 자산 | D11: 해당없음
A12: 141 | B12: 미수금 | C12: 자산 | D12: 해당없음
A13: 150 | B13: 상품 | C13: 자산 | D13: 과세
A14: 160 | B14: 비품 | C14: 자산 | D14: 과세
A15: 165 | B15: 시설장치 | C15: 자산 | D15: 과세
A16: 170 | B16: 감가상각누계액 | C16: 자산 | D16: 해당없음
A17: 180 | B17: 임차보증금 | C17: 자산 | D17: 해당없음
... A58: 540 | B58: 이자비용 | C58: 비용 | D58: 불공제

Sheet 검증
A2: 검증
A3: 입력한 전표를 자동으로 진단합니다. 이 시트는 값을 바꾸지 않습니다.
A4: 확인 필요 항목 수 | C4: =COUNTIF($D$7:$D$15,"확인 필요") -> 0 | D4: =IF(C4=0,"정상","확인 필요") -> 정상
A6: 항목 | B6: 기준 | C6: 결과 | D6: 판정
A7: 대차평형 차액 (총차변 - 총대변) | B7: 0 | C7: =시산표!$B$9 -> 0 | D7: =IF(C7=0,"정상","확인 필요") -> 정상
A8: 전표별 차대 불일치 전표 행 | B8: 0 | C8: =SUM(전표!$Q$7:$Q$282) -> 0 | D8: =IF(C8=0,"정상","확인 필요") -> 정상
A9: 차변·대변 동시 입력 행 | B9: 0 | C9: =SUMPRODUCT((전표!$F$7:$F$282<>"")*(전표!$G$7:$G$282<>"")*1) -> 0 | D9: =IF(C9=0,"정상","확인 필요") -> 정상
A10: 적요만 있고 금액 없는 행 | B10: 0 | C10: =SUMPRODUCT((전표!$D$7:$D$282<>"")*(전표!$F$7:$F$282="")*(전표!$G$7:$G$282="")*1) -> 0 | D10: =IF(C10=0,"정상","확인 필요") -> 정상
A11: 미등록 계정코드 행 | B11: 0 | C11: =COUNTIF(전표!$O$7:$O$282,"미등록") -> 0 | D11: =IF(C11=0,"정상","확인 필요") -> 정상
A12: 날짜 누락 행 | B12: 0 | C12: =SUMPRODUCT((전표!$A$7:$A$282<>"")*(전표!$B$7:$B$282="")*1) -> 0 | D12: =IF(C12=0,"정상","확인 필요") -> 정상
A13: 증빙 미입력 행 | B13: 0 | C13: =SUMPRODUCT((전표!$A$7:$A$282<>"")*(전표!$C$7:$C$282="")*1) -> 0 | D13: =IF(C13=0,"정상","확인 필요") -> 정상
A14: 부가세액 입력·과세 아님 행 | B14: 0 | C14: =SUMPRODUCT((전표!$H$7:$H$282<>"")*(전표!$H$7:$H$282>0)*(전표!$N$7:$N$282<>"과세")*1) -> 0 | D14: =IF(C14=0,"정상","확인 필요") -> 정상
A15: 기간 미표시 행 (날짜 형식 확인) | B15: 0 | C15: =SUMPRODUCT((전표!$A$7:$A$282<>"")*(전표!$K$7:$K$282="")*1) -> 0 | D15: =IF(C15=0,"정상","확인 필요") -> 정상
